Workbook
Name _25_de_agosto: 'RESUMEN TOTAL'!$A$7:$D$498
Name _25_de_agosto_3: 'RESUMEN TOTAL'!$A$7:$D$510
Name _30_mar: #REF!
Name BONOMOcam: Hoja1!$B$2
Name CANTIDAD_DE_CAMARAS: 'RESUMEN TOTAL'!$B$1
Name COSEIDIcam: Hoja1!$B$4

Sheet RESUMEN TOTAL
A1: CANTIDAD DE CAMARAS | B1: =COUNTA(B8:B744) -> 584 | D1: PORCIENTO DE CAIDAS | M1: =(M3)/(M2+M3) -> 0.10566616 | N1: =(N3)/(N2+N3) -> 0.10429448 | O1: =(O3)/(O2+O3) -> 0.10153846 | P1: =(P3)/(P2+P3) -> 0.10839695 | Q1: =(Q3)/(Q2+Q3) -> 0.10429448 | R1: =(R3)/(R2+R3) -> 0.1097561 | S1: =(S3)/(S2+S3) -> 0 | T1: =(T3)/(T2+T3) -> 0 | ... Y1: =(Y3)/(Y2+Y3) -> 0 | AA1: =(AA3)/(AA2+AA3) -> 0 | AB1: =(AB3)/(AB2+AB3) -> 0 | AC1: =(AC3)/(AC2+AC3) -> 0 | AD1: =(AD3)/(AD2+AD3) -> 0 | AE1: =(AE3)/(AE2+AE3) -> 0 | AF1: =(AF3)/(AF2+AF3) -> 0 | AG1: =(AG3)/(AG2+AG3) -> 0 | AH1: =(AH3)/(AH2+AH3) -> 0 | ... AN1: =(AN3)/(AN2+AN3) -> 0
D2: FUNCIONAN | M2: =CANTIDAD_DE_CAMARAS -> 584 | N2: =CANTIDAD_DE_CAMARAS -> 584 | O2: =CANTIDAD_DE_CAMARAS -> 584 | P2: =CANTIDAD_DE_CAMARAS -> 584 | Q2: =CANTIDAD_DE_CAMARAS -> 584 | R2: =CANTIDAD_DE_CAMARAS -> 584 | S2: =CANTIDAD_DE_CAMARAS -> 584 | T2: =CANTIDAD_DE_CAMARAS -> 584 | ... AN2: =CANTIDAD_DE_CAMARAS -> 584
D3: CAIDAS | M3: =COUNTIF(M7:M744, "apagado") -> 69 | N3: =COUNTIF(N7:N744, "apagado") -> 68 | O3: =COUNTIF(O7:O744, "apagado") -> 66 | P3: =COUNTIF(P7:P744, "apagado") -> 71 | Q3: =COUNTIF(Q7:Q744, "apagado") -> 68 | R3: =COUNTIF(R7:R744, "apagado") -> 72 | S3: =COUNTIF(S7:S744, "apagado") -> 0 | T3: =COUNTIF(T7:T744, "apagado") -> 0 | ... AN3: =COUNTIF(AN7:AN744, "apagado") -> 0
D4: APAGADOS FIBRA | M4: =COUNTIFS(M8:M698, "=APAGADO",F8:F698,"=Fibra Optica") -> 30 | N4: =COUNTIFS(N8:N698, "=APAGADO",F8:F698,"=Fibra Optica") -> 31 | O4: =COUNTIFS(O8:O698, "=APAGADO",F8:F698,"=Fibra Optica") -> 30 | P4: =COUNTIFS(P8:P698, "=APAGADO",F8:F698,"=Fibra Optica") -> 30 | Q4: =COUNTIFS(Q8:Q698, "=APAGADO",F8:F698,"=Fibra Optica") -> 25 | R4: =COUNTIFS(R8:R698, "=APAGADO",F8:F698,"=Fibra Optica") -> 27 | S4: =COUNTIFS(S8:S698, "=APAGADO",F8:F698,"=Fibra Optica") -> 0 | T4: =COUNTIFS(T8:T698, "=APAGADO",F8:F698,"=Fibra Optica") -> 0 | U4: =COUNTIFS(U8:U698, "=APAGADO",F8:F698,"=Fibra Optica") -> 33 | V4: =COUNTIFS(V8:V698, "=APAGADO",F8:F698,"=Fibra Optica") -> 55 | W4: =COUNTIFS(W8:W698, "=APAGADO",F8:F698,"=Fibra Optica") -> 42 | X4: =COUNTIFS(X8:X698, "=APAGADO",F8:F698,"=Fibra Optica") -> 49 | Y4: =COUNTIFS(Y8:Y698, "=APAGADO",F8:F698,"=Fibra Optica") -> 0 | Z4: =COUNTIFS(Z8:Z698, "=APAGADO",F8:F698,"=Fibra Optica") -> 0 | AA4: =COUNTIFS(AA8:AA698, "=APAGADO",F8:F698,"=Fibra Optica") -> 0 | AB4: =COUNTIFS(AB8:AB698, "=APAGADO",F8:F698,"=Fibra Optica") -> 0 | AC4: =COUNTIFS(AC8:AC698, "=APAGADO",F8:F698,"=Fibra Optica") -> 0 | AD4: =COUNTIFS(AD8:AD698, "=APAGADO",F8:F698,"=Fibra Optica") -> 0 | AE4: =COUNTIFS(AE8:AE698, "=APAGADO",F8:F698,"=Fibra Optica") -> 0 | AF4: =COUNTIFS(AF8:AF698, "=APAGADO",F8:F698,"=Fibra Optica") -> 0 | AG4: =COUNTIFS(AG8:AG698, "=APAGADO",F8:F698,"=Fibra Optica") -> 0 | AH4: =COUNTIFS(AH8:AH698, "=APAGADO",F8:F698,"=Fibra Optica") -> 0 | AI4: =COUNTIFS(AI8:AI698, "=APAGADO",F8:F698,"=Fibra Optica") -> 0 | AJ4: =COUNTIFS(AJ8:AJ698, "=APAGADO",F8:F698,"=Fibra Optica") -> 0 | AK4: =COUNTIFS(AK8:AK698, "=APAGADO",F8:F698,"=Fibra Optica") -> 0 | AL4: =COUNTIFS(AL8:AL698, "=APAGADO",F8:F698,"=Fibra Optica") -> 0 | AM4: =COUNTIFS(AM8:AM698, "=APAGADO",F8:F698,"=Fibra Optica") -> 0 | AN4: =COUNTIFS(AN8:AN698, "=APAGADO",F8:F698,"=Fibra Optica") -> 0
D5: APAGADOS RADIO | M5: =COUNTIFS(M8:M698, "=APAGADO",F8:F698,"=RADIO") -> 4 | N5: =COUNTIFS(N8:N698, "=APAGADO",F8:F698,"=RADIO") -> 3 | O5: =COUNTIFS(O8:O698, "=APAGADO",F8:F698,"=RADIO") -> 2 | P5: =COUNTIFS(P8:P698, "=APAGADO",F8:F698,"=RADIO") -> 3 | Q5: =COUNTIFS(Q8:Q698, "=APAGADO",F8:F698,"=RADIO") -> 3 | R5: =COUNTIFS(R8:R698, "=APAGADO",F8:F698,"=RADIO") -> 2 | S5: =COUNTIFS(S8:S698, "=APAGADO",F8:F698,"=RADIO") -> 0 | T5: =COUNTIFS(T8:T698, "=APAGADO",F8:F698,"=RADIO") -> 0 | U5: =COUNTIFS(U8:U698, "=APAGADO",F8:F698,"=RADIO") -> 3 | V5: =COUNTIFS(V8:V698, "=APAGADO",F8:F698,"=RADIO") -> 3 | W5: =COUNTIFS(W8:W698, "=APAGADO",F8:F698,"=RADIO") -> 3 | X5: =COUNTIFS(X8:X698, "=APAGADO",F8:F698,"=RADIO") -> 3 | Y5: =COUNTIFS(Y8:Y698, "=APAGADO",F8:F698,"=RADIO") -> 0 | Z5: =COUNTIFS(Z8:Z698, "=APAGADO",F8:F698,"=RADIO") -> 0 | AA5: =COUNTIFS(AA8:AA698, "=APAGADO",F8:F698,"=RADIO") -> 0 | AB5: =COUNTIFS(AB8:AB698, "=APAGADO",F8:F698,"=RADIO") -> 0 | AC5: =COUNTIFS(AC8:AC698, "=APAGADO",F8:F698,"=RADIO") -> 0 | AD5: =COUNTIFS(AD8:AD698, "=APAGADO",F8:F698,"=RADIO") -> 0 | AE5: =COUNTIFS(AE8:AE698, "=APAGADO",F8:F698,"=RADIO") -> 0 | AF5: =COUNTIFS(AF8:AF698, "=APAGADO",F8:F698,"=RADIO") -> 0 | AG5: =COUNTIFS(AG8:AG698, "=APAGADO",F8:F698,"=RADIO") -> 0 | AH5: =COUNTIFS(AH8:AH698, "=APAGADO",F8:F698,"=RADIO") -> 0 | AI5: =COUNTIFS(AI8:AI698, "=APAGADO",F8:F698,"=RADIO") -> 0 | AJ5: =COUNTIFS(AJ8:AJ698, "=APAGADO",F8:F698,"=RADIO") -> 0 | AK5: =COUNTIFS(AK8:AK698, "=APAGADO",F8:F698,"=RADIO") -> 0 | AL5: =COUNTIFS(AL8:AL698, "=APAGADO",F8:F698,"=RADIO") -> 0 | AM5: =COUNTIFS(AM8:AM698, "=APAGADO",F8:F698,"=RADIO") -> 0 | AN5: =COUNTIFS(AN8:AN698, "=APAGADO",F8:F698,"=RADIO") -> 0
D6: APAGADOS ANTENA | M6: =COUNTIFS(M8:M698, "=APAGADO",F8:F698,"=PTO A FO") -> 10 | N6: =COUNTIFS(N8:N698, "=APAGADO",F8:F698,"=PTO A FO") -> 11 | O6: =COUNTIFS(O8:O698, "=APAGADO",F8:F698,"=PTO A FO") -> 11 | P6: =COUNTIFS(P8:P698, "=APAGADO",F8:F698,"=PTO A FO") -> 13 | Q6: =COUNTIFS(Q8:Q698, "=APAGADO",F8:F698,"=PTO A FO") -> 16 | R6: =COUNTIFS(R8:R698, "=APAGADO",F8:F698,"=PTO A FO") -> 17 | S6: =COUNTIFS(S8:S698, "=APAGADO",F8:F698,"=PTO A FO") -> 0 | T6: =COUNTIFS(T8:T698, "=APAGADO",F8:F698,"=PTO A FO") -> 0 | U6: =COUNTIFS(U8:U698, "=APAGADO",F8:F698,"=PTO A FO") -> 16 | V6: =COUNTIFS(V8:V698, "=APAGADO",F8:F698,"=PTO A FO") -> 14 | W6: =COUNTIFS(W8:W698, "=APAGADO",F8:F698,"=PTO A FO") -> 11 | X6: =COUNTIFS(X8:X698, "=APAGADO",F8:F698,"=PTO A FO") -> 13 | Y6: =COUNTIFS(Y8:Y698, "=APAGADO",F8:F698,"=PTO A FO") -> 0 | Z6: =COUNTIFS(Z8:Z698, "=APAGADO",F8:F698,"=PTO A FO") -> 0 | AA6: =COUNTIFS(AA8:AA698, "=APAGADO",F8:F698,"=PTO A FO") -> 0 | AB6: =COUNTIFS(AB8:AB698, "=APAGADO",F8:F698,"=PTO A FO") -> 0 | AC6: =COUNTIFS(AC8:AC698, "=APAGADO",F8:F698,"=PTO A FO") -> 0 | AD6: =COUNTIFS(AD8:AD698, "=APAGADO",F8:F698,"=PTO A FO") -> 0 | AE6: =COUNTIFS(AE8:AE698, "=APAGADO",F8:F698,"=PTO A FO") -> 0 | AF6: =COUNTIFS(AF8:AF698, "=APAGADO",F8:F698,"=PTO A FO") -> 0 | AG6: =COUNTIFS(AG8:AG698, "=APAGADO",F8:F698,"=PTO A FO") -> 0 | AH6: =COUNTIFS(AH8:AH698, "=APAGADO",F8:F698,"=PTO A FO") -> 0 | AI6: =COUNTIFS(AI8:AI698, "=APAGADO",F8:F698,"=PTO A FO") -> 0 | AJ6: =COUNTIFS(AJ8:AJ698, "=APAGADO",F8:F698,"=PTO A FO") -> 0 | AK6: =COUNTIFS(AK8:AK698, "=APAGADO",F8:F698,"=PTO A FO") -> 0 | AL6: =COUNTIFS(AL8:AL698, "=APAGADO",F8:F698,"=PTO A FO") -> 0 | AM6: =COUNTIFS(AM8:AM698, "=APAGADO",F8:F698,"=PTO A FO") -> 0 | AN6: =COUNTIFS(AN8:AN698, "=APAGADO",F8:F698,"=PTO A FO") -> 0
A7: Barrio | B7: [Denominacion] | C7: [Empresa Mantenimiento] | D7: [Ubicacion] | E7: [Tipo de Camara] | F7: [Tipo de Conexion] | G7: Destino | H7: [IP] | I7: DIAS FUNCIONANDO | J7: MAC | K7: DIAS CAIDA | L7: EFECTIVIDAD | M7: 46054 | N7: 46055 | O7: 46056 | P7: 46057 | Q7: 46058 | R7: 46059 | S7: 46060 | T7: 46061 | U7: 46062 | V7: 46063 | W7: 46064 | X7: 46065 | Y7: 46066 | Z7: 46067 | AA7: 46068 | AB7: 46069 | AC7: 46070 | AD7: 46071 | AE7: 46072 | AF7: 46073 | AG7: 46074 | AH7: 46075 | AI7: 46076 | AJ7: 46077 | AK7: 46078 | AL7: 46079 | AM7: 46080 | AN7: 46081
A8: ALTAMIRA | B8: ALT01 | C8: BONOMO | D8: Calchaqui y Sgto. Cabral | E8: Domo | F8: Fibra Optica | H8: 172.20.10.6 | I8: =COUNTIF(M8:AN8,"") -> 21 | J8: 00-07-5F-87-83-56 | K8: =COUNTIF(M8:AN8,"APAGADO") -> 7 | L8: =(I8)/(K8+I8) -> 0.75 | P8: APAGADO | Q8: APAGADO | R8: APAGADO | U8: APAGADO | V8: APAGADO | W8: APAGADO | X8: APAGADO
A9: ALTAMIRA | B9: ALT02 | C9: BONOMO | D9: Calchaqui y Lope de Vega | E9: Domo | F9: PTO A FO | G9: CABRAL Y CALCHAQUI | H9: 172.20.12.218 | I9: =COUNTIF(M9:AN9,"") -> 18 | J9: 00-04-63-50-42-A4 | K9: =COUNTIF(M9:AN9,"APAGADO") -> 10 | L9: =(I9)/(K9+I9) -> 0.64285714 | M9: APAGADO | N9: APAGADO | O9: APAGADO | P9: APAGADO | Q9: APAGADO | R9: APAGADO | U9: APAGADO | V9: APAGADO | W9: APAGADO | X9: APAGADO
A10: ALTAMIRA | B10: ALT 03 | C10: BONOMO | D10: Bombero Galarza y Necochea | E10: Domo | F10: GPON | H10: 172.20.12.54 | I10: =COUNTIF(M10:AN10,"") -> 28 | J10: 00-07-5F-87-9D-EF | K10: =COUNTIF(M10:AN10,"APAGADO") -> 0 | L10: =(I10)/(K10+I10) -> 1
A11: ALTAMIRA | B11: ALT 04 | C11: BONOMO | D11: Francia y Necochea | E11: Domo | F11: GPON | H11: 172.20.12.55 | I11: =COUNTIF(M11:AN11,"") -> 28 | J11: 00-04-63-59-22-57 | K11: =COUNTIF(M11:AN11,"APAGADO") -> 0 | L11: =(I11)/(K11+I11) -> 1
A12: ALTAMIRA | B12: ALT05 | C12: BONOMO | D12: Av. Calchaqui y Bombero Galarza | E12: Domo | F12: GPON | G12: NECOCHEA Y GALARZA | H12: 172.20.12.216 | I12: =COUNTIF(M12:AN12,"") -> 28 | J12: 00-07-5F-77-02-85 | K12: =COUNTIF(M12:AN12,"APAGADO") -> 0 | L12: =(I12)/(K12+I12) -> 1
A13: ALTAMIRA | B13: ALT 06 | C13: BONOMO | D13: LOPE DE VEGA Y NECOCHEA | E13: Domo | F13: GPON | G13: NECOCHEA Y GALARZA | H13: 172.20.12.12 | I13: =COUNTIF(M13:AN13,"") -> 28 | J13: 00-04-63-4F-DD-DB | K13: =COUNTIF(M13:AN13,"APAGADO") -> 0 | L13: =(I13)/(K13+I13) -> 1
A14: ALTAMIRA | B14: ALT07 | C14: BONOMO | D14: AV. CALCHAQUI Y AV. DEL TRABAJO | E14: DOMO | F14: PTO A FO | G14: CABRAL Y CALCHAQUI | H14: 172.20.10.57 | I14: =COUNTIF(M14:AN14,"") -> 21 | J14: 00-04-63-4F-DE-CA | K14: =COUNTIF(M14:AN14,"APAGADO") -> 7 | L14: =(I14)/(K14+I14) -> 0.75 | P14: APAGADO | Q14: APAGADO | R14: APAGADO | U14: APAGADO | V14: APAGADO | W14: APAGADO | X14: APAGADO
A15: ALTAMIRA | B15: ALT 08 | C15: BONOMO | D15: HUMAITA Y NECOCHEA | E15: DOMO | F15: Fibra Optica | H15: 172.20.11.215 | I15: =COUNTIF(M15:AN15,"") -> 28 | J15: 00-07-5F-BE-59-2D | K15: =COUNTIF(M15:AN15,"APAGADO") -> 0 | L15: =(I15)/(K15+I15) -> 1
A16: ALTAMIRA | B16: ALT 09 | C16: BONOMO | D16: NECOCHEA Y CURUPAITY | E16: DOMO | F16: Fibra Optica | H16: 172.20.11.216 | I16: =COUNTIF(M16:AN16,"") -> 28 | J16: 00-07-5F-BE-59-27 | K16: =COUNTIF(M16:AN16,"APAGADO") -> 0 | L16: =(I16)/(K16+I16) -> 1
A17: ALTAMIRA | B17: ALT 10 | C17: BONOMO | D17: Calchaqui y Francia | E17: Domo | F17: GPON | H17: 172.20.12.156 | I17: =COUNTIF(M17:AN17,"") -> 28 | J17: 00-07-5F-AB-BB-41 | K17: =COUNTIF(M17:AN17,"APAGADO") -> 0 | L17: =(I17)/(K17+I17) -> 1
A18: ALTAMIRA | B18: ALT 11 | C18: BONOMO | D18: CALCHAQUÍ Y GALARZA FIJA | E18: Fija | F18: GPON | H18: 172.20.12.241 | I18: =COUNTIF(M18:AN18,"") -> 28 | J18: 3c-1b-f8-df-95-58 | K18: =COUNTIF(M18:AN18,"APAGADO") -> 0 | L18: =(I18)/(K18+I18) -> 1
A19: AGUSTIN RAMIREZ | B19: ARA 01 | C19: BONOMO | D19: Malambo y Tranquera | E19: Domo | F19: Fibra Optica | H19: 172.20.12.110 | I19: =COUNTIF(M19:AN19,"") -> 18 | J19: 00-04-63-4F-DB-B6 | K19: =COUNTIF(M19:AN19,"APAGADO") -> 10 | L19: =(I19)/(K19+I19) -> 0.64285714 | M19: APAGADO | N19: APAGADO | O19: APAGADO | P19: APAGADO | Q19: APAGADO | R19: APAGADO | U19: APAGADO | V19: APAGADO | W19: APAGADO | X19: APAGADO
A20: AGUSTIN RAMIREZ | B20: ARA 02 | C20: BONOMO | D20: El malambo y La Tranquera | E20: Fija | F20: GPON | H20: 172.20.12.235 | I20: =COUNTIF(M20:AN20,"") -> 18 | J20: C0:6D:ED:A3:E6:63 | K20: =COUNTIF(M20:AN20,"APAGADO") -> 10 | L20: =(I20)/(K20+I20) -> 0.64285714 | M20: APAGADO | N20: APAGADO | O20: APAGADO | P20: APAGADO | Q20: APAGADO | R20: APAGADO | U20: APAGADO | V20: APAGADO | W20: APAGADO | X20: APAGADO
A21: AGUSTIN RAMIREZ | B21: ARA 03 | C21: BONOMO | D21: 437 Y La Tranquera | E21: Fija | F21: GPON | H21: 172.20.10.232 | I21: =COUNTIF(M21:AN21,"") -> 28 | J21: C0:6D:ED:A3:66:6A | K21: =COUNTIF(M21:AN21,"APAGADO") -> 0 | L21: =(I21)/(K21+I21) -> 1
A22: BELGRANO | B22: BEL 01 | C22: BONOMO | D22: San Martin y Dardo Rocha | E22: DOMO | F22: Fibra Optica | H22: 172.20.12.64 | I22: =COUNTIF(M22:AN22,"") -> 28 | J22: 00-07-5F-81-B9-E9 | K22: =COUNTIF(M22:AN22,"APAGADO") -> 0 | L22: =(I22)/(K22+I22) -> 1
A23: BELGRANO | B23: BEL 02 | C23: BONOMO | D23: Guardia vieja y Fronteriz | E23: DOMO | F23: Fibra Optica | H23: 172.20.10.117 | I23: =COUNTIF(M23:AN23,"") -> 28 | J23: E4-30-22-4F-9E-62 | K23: =COUNTIF(M23:AN23,"APAGADO") -> 0 | L23: =(I23)/(K23+I23) -> 1
A24: BOSQUES CENTRO | B24: BOSQC 01 | C24: COSEIDI | D24: LUIS AGOTE E/DANUNCIO Y CAMPOAMOR | E24: Fija | F24: PTO A FO | H24: 172.20.11.15 | I24: =COUNTIF(M24:AN24,"") -> 24 | J24: 00-07-5F-B7-56-89 | K24: =COUNTIF(M24:AN24,"APAGADO") -> 4 | L24: =(I24)/(K24+I24) -> 0.85714286 | Q24: APAGADO | R24: APAGADO | U24: APAGADO | V24: APAGADO
A25: BOSQUES CENTRO | B25: BOSQC 02 | C25: COSEIDI | D25: LUIS AGOTE E/DANUNCIO Y CAMPOAMOR | E25: Fija | F25: PTO A FO | H25: 172.20.11.16 | I25: =COUNTIF(M25:AN25,"") -> 24 | J25: 00-07-5F-B4-17-A8 | K25: =COUNTIF(M25:AN25,"APAGADO") -> 4 | L25: =(I25)/(K25+I25) -> 0.85714286 | Q25: APAGADO | R25: APAGADO | U25: APAGADO | V25: APAGADO
A26: BOSQUES CENTRO | B26: BOSQC 03 | C26: COSEIDI | D26: BENAVENTE Y LUIS AGOTE | E26: Fija | F26: PTO A FO | H26: 172.20.11.13 | I26: =COUNTIF(M26:AN26,"") -> 24 | J26: 00-07-5F-B6-B8-A5 | K26: =COUNTIF(M26:AN26,"APAGADO") -> 4 | L26: =(I26)/(K26+I26) -> 0.85714286 | Q26: APAGADO | R26: APAGADO | U26: APAGADO | V26: APAGADO
A27: BOSQUES CENTRO | B27: BOSQC 04 | C27: COSEIDI | D27: BENAVENTE Y LUIS AGOTE | E27: Fija | F27: PTO A FO | H27: 172.20.11.113 | I27: =COUNTIF(M27:AN27,"") -> 24 | J27: 00-07-5F-B6-B8-D3 | K27: =COUNTIF(M27:AN27,"APAGADO") -> 4 | L27: =(I27)/(K27+I27) -> 0.85714286 | Q27: APAGADO | R27: APAGADO | U27: APAGADO | V27: APAGADO
A28: BOSQUES CENTRO | B28: BOSQC 05 | C28: COSEIDI | D28: LUIS AGOTE Y RUTA 36 | E28: Fija | F28: PTO A FO | H28: 172.20.11.17 | I28: =COUNTIF(M28:AN28,"") -> 28 | J28: 00-07-5F-B4-42-C7 | K28: =COUNTIF(M28:AN28,"APAGADO") -> 0 | L28: =(I28)/(K28+I28) -> 1
A29: BOSQUES CENTRO | B29: BOSQC 06 | C29: COSEIDI | D29: LUIS AGOTE Y RUTA 36 | E29: Fija | F29: PTO A FO | H29: 172.20.11.18 | I29: =COUNTIF(M29:AN29,"") -> 28 | J29: 00-07-5F-B4-16-8D | K29: =COUNTIF(M29:AN29,"APAGADO") -> 0 | L29: =(I29)/(K29+I29) -> 1
A30: BOSQUES CENTRO | B30: BOSQC 07 | C30: BONOMO | D30: Touring club y Sta Teresita | E30: Domo | F30: GPON | H30: 172.20.10.141 | I30: =COUNTIF(M30:AN30,"") -> 28 | J30: A0-FF-0C-D1-BD-7F | K30: =COUNTIF(M30:AN30,"APAGADO") -> 0 | L30: =(I30)/(K30+I30) -> 1
A31: BOSQUES CENTRO | B31: BOSQC 08 | C31: COSEIDI | D31: D'Anuncio Y J.B Justo (Plaza) | E31: Domo | F31: GPON | H31: 172.20.10.222 | I31: =COUNTIF(M31:AN31,"") -> 28 | J31: a4-18-94-05-51-13 | K31: =COUNTIF(M31:AN31,"APAGADO") -> 0 | L31: =(I31)/(K31+I31) -> 1
A32: BOSQUES CENTRO | B32: BOSQC 09 | C32: COSEIDI | D32: D'Anuncio e/Lisandro de la Torre y J.B Justo | E32: Fija | F32: GPON | H32: 172.20.10.227 | I32: =COUNTIF(M32:AN32,"") -> 28 | J32: c0-6d-ed-a3-e4-4c | K32: =COUNTIF(M32:AN32,"APAGADO") -> 0 | L32: =(I32)/(K32+I32) -> 1
A33: BOSQUES CENTRO | B33: BOSQC 10 | C33: COSEIDI | D33: D'Anuncio e/Lisandro de la Torre y J.B Justo | E33: Fija | F33: GPON | H33: 172.20.10.228 | I33: =COUNTIF(M33:AN33,"") -> 28 | J33: c0-6d-ed-a3-e4-5b | K33: =COUNTIF(M33:AN33,"APAGADO") -> 0 | L33: =(I33)/(K33+I33) -> 1
A34: BOSQUES CENTRO | B34: BOSQC 11 | C34: COSEIDI | D34: AV Bosques y Altagracia | E34: Domo | F34: GPON | H34: 172.20.8.52 | I34: =COUNTIF(M34:AN34,"") -> 28 | J34: A4-18-94-05-A4-68 | K34: =COUNTIF(M34:AN34,"APAGADO") -> 0 | L34: =(I34)/(K34+I34) -> 1
A35: PRESIDENTE AVELLANEDA | B35: PAVE01 | C35: COSEIDI | D35: Touring Club y Ramallo | E35: Domo | F35: Fibra Optica | H35: 172.20.10.144 | I35: =COUNTIF(M35:AN35,"") -> 18 | J35: A0-FF-0C-D4-AF-AD | K35: =COUNTIF(M35:AN35,"APAGADO") -> 10 | L35: =(I35)/(K35+I35) -> 0.64285714 | M35: APAGADO | N35: APAGADO | O35: APAGADO | P35: APAGADO | Q35: APAGADO | R35: APAGADO | U35: APAGADO | V35: APAGADO | W35: APAGADO | X35: APAGADO
A36: PRESIDENTE AVELLANEDA | B36: PAVE02 | C36: COSEIDI | D36: Ramallo y Calingasta | E36: Domo | F36: GPON | H36: 172.20.10.37 | I36: =COUNTIF(M36:AN36,"") -> 20 | J36: a4-18-94-05-47-33 | K36: =COUNTIF(M36:AN36,"APAGADO") -> 8 | L36: =(I36)/(K36+I36) -> 0.71428571 | O36: APAGADO | P36: APAGADO | Q36: APAGADO | R36: APAGADO | U36: APAGADO | V36: APAGADO | W36: APAGADO | X36: APAGADO
A37: PRESIDENTE AVELLANEDA | B37: PAVE03 | C37: COSEIDI | D37: Ptagones e Irala | E37: Domo | F37: GPON | H37: 172,20,12,201 | I37: =COUNTIF(M37:AN37,"") -> 18 | J37: a4-18-94-05-50-c9 | K37: =COUNTIF(M37:AN37,"APAGADO") -> 10 | L37: =(I37)/(K37+I37) -> 0.64285714 | M37: APAGADO | N37: APAGADO | O37: APAGADO | P37: APAGADO | Q37: APAGADO | R37: APAGADO | U37: APAGADO | V37: APAGADO | W37: APAGADO | X37: APAGADO
A38: BOSQUES CENTRO | B38: CVA01 | C38: COSEIDI | D38: CACHEUTA Y 1355 | E38: Domo | F38: GPON | H38: 172.20.10.59 | I38: =COUNTIF(M38:AN38,"") -> 28 | J38: c0-6d-ed-a7-2f-76 | K38: =COUNTIF(M38:AN38,"APAGADO") -> 0 | L38: =(I38)/(K38+I38) -> 1
A39: LA CAROLINA 2 | B39: CAR01 (Fija 1) | C39: COSEIDI | D39: Azurduy y Vergara | E39: Fija | F39: Fibra Optica | H39: 172.20.10.60 | I39: =COUNTIF(M39:AN39,"") -> 28 | J39: A0:FF:0C:EF:DF:AB | K39: =COUNTIF(M39:AN39,"APAGADO") -> 0 | L39: =(I39)/(K39+I39) -> 1
A40: LA CAROLINA 2 | B40: CAR02 (Fija 2) | C40: COSEIDI | D40: Azurduy y Vergara | E40: Fija | F40: Fibra Optica | H40: 172.20.10.73 | I40: =COUNTIF(M40:AN40,"") -> 28 | J40: A0:FF:0C:EF:DF:AD | K40: =COUNTIF(M40:AN40,"APAGADO") -> 0 | L40: =(I40)/(K40+I40) -> 1
...

Sheet AUXILIAR

Sheet paradas
C1: TOTAL PARADAS | D1: =COUNTIFS(A5:A602,"=paradas seguras")/2 -> 0 | E1: TOTAL DE CAMARAS EN PARADAS | H1: =COUNTIFS(A5:A602,"=paradas seguras") -> 0 | I1: TOTAL DE CAMARAS | K1: =COUNTIFS(D5:D602,"=GFIJA") -> 0 | L1: TOTAL DE INTERCOMUNICADORES | O1: =COUNTIFS(D5:D602,"=INTERCOMUNICADOR") -> 0
E2: FIJAS | F2: =COUNTIFS(F4:F601, "=APAGADO",D4:D601,"=GFIJA") -> 0 | G2: =COUNTIFS(G4:G601, "=APAGADO",D4:D601,"=GFIJA") -> 0 | H2: =COUNTIFS(H4:H601, "=APAGADO",D4:D601,"=GFIJA") -> 0 | I2: =COUNTIFS(I4:I601, "=APAGADO",D4:D601,"=GFIJA") -> 0 | J2: =COUNTIFS(J4:J601, "=APAGADO",D4:D601,"=GFIJA") -> 0 | K2: =COUNTIFS(K4:K601, "=APAGADO",D4:D601,"=GFIJA") -> 0 | L2: =COUNTIFS(L4:L601, "=APAGADO",D4:D601,"=GFIJA") -> 0 | M2: =COUNTIFS(M4:M601, "=APAGADO",D4:D601,"=GFIJA") -> 0 | N2: =COUNTIFS(N4:N601, "=APAGADO",D4:D601,"=GFIJA") -> 0 | O2: =COUNTIFS(O4:O601, "=APAGADO",D4:D601,"=GFIJA") -> 0 | P2: =COUNTIFS(P4:P601, "=APAGADO",D4:D601,"=GFIJA") -> 0 | Q2: =COUNTIFS(Q4:Q601, "=APAGADO",D4:D601,"=GFIJA") -> 0 | R2: =COUNTIFS(R4:R601, "=APAGADO",D4:D601,"=GFIJA") -> 0 | S2: =COUNTIFS(S4:S601, "=APAGADO",D4:D601,"=GFIJA") -> 0 | T2: =COUNTIFS(T4:T601, "=APAGADO",D4:D601,"=GFIJA") -> 0 | U2: =COUNTIFS(U4:U601, "=APAGADO",D4:D601,"=GFIJA") -> 0 | V2: =COUNTIFS(V4:V601, "=APAGADO",D4:D601,"=GFIJA") -> 0 | W2: =COUNTIFS(W4:W601, "=APAGADO",D4:D601,"=GFIJA") -> 0 | X2: =COUNTIFS(X4:X601, "=APAGADO",D4:D601,"=GFIJA") -> 0 | Y2: =COUNTIFS(Y4:Y601, "=APAGADO",D4:D601,"=GFIJA") -> 0 | Z2: =COUNTIFS(Z4:Z601, "=APAGADO",D4:D601,"=GFIJA") -> 0 | AA2: =COUNTIFS(AA4:AA601, "=APAGADO",D4:D601,"=GFIJA") -> 0 | AB2: =COUNTIFS(AB4:AB601, "=APAGADO",D4:D601,"=GFIJA") -> 0 | AC2: =COUNTIFS(AC4:AC601, "=APAGADO",D4:D601,"=GFIJA") -> 0 | AD2: =COUNTIFS(AD4:AD601, "=APAGADO",D4:D601,"=GFIJA") -> 0 | AE2: =COUNTIFS(AE4:AE601, "=APAGADO",D4:D601,"=GFIJA") -> 0 | AF2: =COUNTIFS(AF4:AF601, "=APAGADO",D4:D601,"=GFIJA") -> 0 | AG2: =COUNTIFS(AG4:AG601, "=APAGADO",D4:D601,"=GFIJA") -> 0
E3: INTERCOMUNICADOR | F3: =COUNTIFS(F6:F603, "=APAGADO",D4:D601,"=INTERCOMUNICADOR") -> 0 | G3: =COUNTIFS(G6:G603, "=APAGADO",D4:D601,"=INTERCOMUNICADOR") -> 0 | H3: =COUNTIFS(H6:H603, "=APAGADO",D4:D601,"=INTERCOMUNICADOR") -> 0 | I3: =COUNTIFS(I6:I603, "=APAGADO",D4:D601,"=INTERCOMUNICADOR") -> 0 | J3: =COUNTIFS(J6:J603, "=APAGADO",D4:D601,"=INTERCOMUNICADOR") -> 0 | K3: =COUNTIFS(K6:K603, "=APAGADO",D4:D601,"=INTERCOMUNICADOR") -> 0 | L3: =COUNTIFS(L6:L603, "=APAGADO",D4:D601,"=INTERCOMUNICADOR") -> 0 | M3: =COUNTIFS(M6:M603, "=APAGADO",D4:D601,"=INTERCOMUNICADOR") -> 0 | N3: =COUNTIFS(N6:N603, "=APAGADO",D4:D601,"=INTERCOMUNICADOR") -> 0 | O3: =COUNTIFS(O6:O603, "=APAGADO",D4:D601,"=INTERCOMUNICADOR") -> 0 | P3: =COUNTIFS(P6:P603, "=APAGADO",D4:D601,"=INTERCOMUNICADOR") -> 0 | Q3: =COUNTIFS(Q6:Q603, "=APAGADO",D4:D601,"=INTERCOMUNICADOR") -> 0 | R3: =COUNTIFS(R6:R603, "=APAGADO",D4:D601,"=INTERCOMUNICADOR") -> 0 | S3: =COUNTIFS(S6:S603, "=APAGADO",D4:D601,"=INTERCOMUNICADOR") -> 0 | T3: =COUNTIFS(T6:T603, "=APAGADO",D4:D601,"=INTERCOMUNICADOR") -> 0 | U3: =COUNTIFS(U6:U603, "=APAGADO",D4:D601,"=INTERCOMUNICADOR") -> 0 | V3: =COUNTIFS(V6:V603, "=APAGADO",D4:D601,"=INTERCOMUNICADOR") -> 0 | W3: =COUNTIFS(W6:W603, "=APAGADO",D4:D601,"=INTERCOMUNICADOR") -> 0 | X3: =COUNTIFS(X6:X603, "=APAGADO",D4:D601,"=INTERCOMUNICADOR") -> 0 | Y3: =COUNTIFS(Y6:Y603, "=APAGADO",D4:D601,"=INTERCOMUNICADOR") -> 0 | Z3: =COUNTIFS(Z6:Z603, "=APAGADO",D4:D601,"=INTERCOMUNICADOR") -> 0 | AA3: =COUNTIFS(AA6:AA603, "=APAGADO",D4:D601,"=INTERCOMUNICADOR") -> 0 | AB3: =COUNTIFS(AB6:AB603, "=APAGADO",D4:D601,"=INTERCOMUNICADOR") -> 0 | AC3: =COUNTIFS(AC6:AC603, "=APAGADO",D4:D601,"=INTERCOMUNICADOR") -> 0 | AD3: =COUNTIFS(AD6:AD603, "=APAGADO",D4:D601,"=INTERCOMUNICADOR") -> 0 | AE3: =COUNTIFS(AE6:AE603, "=APAGADO",D4:D601,"=INTERCOMUNICADOR") -> 0 | AF3: =COUNTIFS(AF6:AF603, "=APAGADO",D4:D601,"=INTERCOMUNICADOR") -> 0 | AG3: =COUNTIFS(AG6:AG603, "=APAGADO",D4:D601,"=INTERCOMUNICADOR") -> 0
A4: ='RESUMEN TOTAL'!A7 -> Barrio | B4: ='RESUMEN TOTAL'!B7 -> [Denominacion] | C4: ='RESUMEN TOTAL'!D7 -> [Ubicacion] | D4: ='RESUMEN TOTAL'!E7 -> [Tipo de Camara] | E4: ='RESUMEN TOTAL'!F7 -> [Tipo de Conexion] | F4: ='RESUMEN TOTAL'!M7 -> 46054 | G4: ='RESUMEN TOTAL'!N7 -> 46055 | H4: ='RESUMEN TOTAL'!O7 -> 46056 | I4: ='RESUMEN TOTAL'!P7 -> 46057 | J4: ='RESUMEN TOTAL'!Q7 -> 46058 | K4: ='RESUMEN TOTAL'!R7 -> 46059 | L4: ='RESUMEN TOTAL'!S7 -> 46060 | M4: ='RESUMEN TOTAL'!T7 -> 46061 | ... AG4: ='RESUMEN TOTAL'!AN7 -> 46081 | XEY4: =SUM(F4:XEX4) -> 1289890
A5: ='RESUMEN TOTAL'!A8 -> ALTAMIRA | B5: ='RESUMEN TOTAL'!B8 -> ALT01 | C5: ='RESUMEN TOTAL'!D8 -> Calchaqui y Sgto. Cabral | D5: ='RESUMEN TOTAL'!E8 -> Domo | E5: ='RESUMEN TOTAL'!F8 -> Fibra Optica | F5: ='RESUMEN TOTAL'!M8 -> 0 | G5: ='RESUMEN TOTAL'!N8 -> 0 | H5: ='RESUMEN TOTAL'!O8 -> 0 | I5: ='RESUMEN TOTAL'!P8 -> APAGADO | J5: ='RESUMEN TOTAL'!Q8 -> APAGADO | K5: ='RESUMEN TOTAL'!R8 -> APAGADO | L5: ='RESUMEN TOTAL'!S8 -> 0 | M5: ='RESUMEN TOTAL'!T8 -> 0 | ... AG5: ='RESUMEN TOTAL'!AN8 -> 0
A6: ='RESUMEN TOTAL'!A9 -> ALTAMIRA | B6: ='RESUMEN TOTAL'!B9 -> ALT02 | C6: ='RESUMEN TOTAL'!D9 -> Calchaqui y Lope de Vega | D6: ='RESUMEN TOTAL'!E9 -> Domo | E6: ='RESUMEN TOTAL'!F9 -> PTO A FO | F6: ='RESUMEN TOTAL'!M9 -> APAGADO | G6: ='RESUMEN TOTAL'!N9 -> APAGADO | H6: ='RESUMEN TOTAL'!O9 -> APAGADO | I6: ='RESUMEN TOTAL'!P9 -> APAGADO | J6: ='RESUMEN TOTAL'!Q9 -> APAGADO | K6: ='RESUMEN TOTAL'!R9 -> APAGADO | L6: ='RESUMEN TOTAL'!S9 -> 0 | M6: ='RESUMEN TOTAL'!T9 -> 0 | ... AG6: ='RESUMEN TOTAL'!AN9 -> 0
A7: ='RESUMEN TOTAL'!A10 -> ALTAMIRA | B7: ='RESUMEN TOTAL'!B10 -> ALT 03 | C7: ='RESUMEN TOTAL'!D10 -> Bombero Galarza y Necochea | D7: ='RESUMEN TOTAL'!E10 -> Domo | E7: ='RESUMEN TOTAL'!F10 -> GPON | F7: ='RESUMEN TOTAL'!M10 -> 0 | G7: ='RESUMEN TOTAL'!N10 -> 0 | H7: ='RESUMEN TOTAL'!O10 -> 0 | I7: ='RESUMEN TOTAL'!P10 -> 0 | J7: ='RESUMEN TOTAL'!Q10 -> 0 | K7: ='RESUMEN TOTAL'!R10 -> 0 | L7: ='RESUMEN TOTAL'!S10 -> 0 | M7: ='RESUMEN TOTAL'!T10 -> 0 | ... AG7: ='RESUMEN TOTAL'!AN10 -> 0
A8: ='RESUMEN TOTAL'!A11 -> ALTAMIRA | B8: ='RESUMEN TOTAL'!B11 -> ALT 04 | C8: ='RESUMEN TOTAL'!D11 -> Francia y Necochea | D8: ='RESUMEN TOTAL'!E11 -> Domo | E8: ='RESUMEN TOTAL'!F11 -> GPON | F8: ='RESUMEN TOTAL'!M11 -> 0 | G8: ='RESUMEN TOTAL'!N11 -> 0 | H8: ='RESUMEN TOTAL'!O11 -> 0 | I8: ='RESUMEN TOTAL'!P11 -> 0 | J8: ='RESUMEN TOTAL'!Q11 -> 0 | K8: ='RESUMEN TOTAL'!R11 -> 0 | L8: ='RESUMEN TOTAL'!S11 -> 0 | M8: ='RESUMEN TOTAL'!T11 -> 0 | ... AG8: ='RESUMEN TOTAL'!AN11 -> 0
A9: ='RESUMEN TOTAL'!A12 -> ALTAMIRA | B9: ='RESUMEN TOTAL'!B12 -> ALT05 | C9: ='RESUMEN TOTAL'!D12 -> Av. Calchaqui y Bombero Galarza | D9: ='RESUMEN TOTAL'!E12 -> Domo | E9: ='RESUMEN TOTAL'!F12 -> GPON | F9: ='RESUMEN TOTAL'!M12 -> 0 | G9: ='RESUMEN TOTAL'!N12 -> 0 | H9: ='RESUMEN TOTAL'!O12 -> 0 | I9: ='RESUMEN TOTAL'!P12 -> 0 | J9: ='RESUMEN TOTAL'!Q12 -> 0 | K9: ='RESUMEN TOTAL'!R12 -> 0 | L9: ='RESUMEN TOTAL'!S12 -> 0 | M9: ='RESUMEN TOTAL'!T12 -> 0 | ... AG9: ='RESUMEN TOTAL'!AN12 -> 0
A10: ='RESUMEN TOTAL'!A13 -> ALTAMIRA | B10: ='RESUMEN TOTAL'!B13 -> ALT 06 | C10: ='RESUMEN TOTAL'!D13 -> LOPE DE VEGA Y NECOCHEA | D10: ='RESUMEN TOTAL'!E13 -> Domo | E10: ='RESUMEN TOTAL'!F13 -> GPON | F10: ='RESUMEN TOTAL'!M13 -> 0 | G10: ='RESUMEN TOTAL'!N13 -> 0 | H10: ='RESUMEN TOTAL'!O13 -> 0 | I10: ='RESUMEN TOTAL'!P13 -> 0 | J10: ='RESUMEN TOTAL'!Q13 -> 0 | K10: ='RESUMEN TOTAL'!R13 -> 0 | L10: ='RESUMEN TOTAL'!S13 -> 0 | M10: ='RESUMEN TOTAL'!T13 -> 0 | ... AG10: ='RESUMEN TOTAL'!AN13 -> 0
A11: ='RESUMEN TOTAL'!A14 -> ALTAMIRA | B11: ='RESUMEN TOTAL'!B14 -> ALT07 | C11: ='RESUMEN TOTAL'!D14 -> AV. CALCHAQUI Y AV. DEL TRABAJO | D11: ='RESUMEN TOTAL'!E14 -> DOMO | E11: ='RESUMEN TOTAL'!F14 -> PTO A FO | F11: ='RESUMEN TOTAL'!M14 -> 0 | G11: ='RESUMEN TOTAL'!N14 -> 0 | H11: ='RESUMEN TOTAL'!O14 -> 0 | I11: ='RESUMEN TOTAL'!P14 -> APAGADO | J11: ='RESUMEN TOTAL'!Q14 -> APAGADO | K11: ='RESUMEN TOTAL'!R14 -> APAGADO | L11: ='RESUMEN TOTAL'!S14 -> 0 | M11: ='RESUMEN TOTAL'!T14 -> 0 | ... AG11: ='RESUMEN TOTAL'!AN14 -> 0
A12: ='RESUMEN TOTAL'!A15 -> ALTAMIRA | B12: ='RESUMEN TOTAL'!B15 -> ALT 08 | C12: ='RESUMEN TOTAL'!D15 -> HUMAITA Y NECOCHEA | D12: ='RESUMEN TOTAL'!E15 -> DOMO | E12: ='RESUMEN TOTAL'!F15 -> Fibra Optica | F12: ='RESUMEN TOTAL'!M15 -> 0 | G12: ='RESUMEN TOTAL'!N15 -> 0 | H12: ='RESUMEN TOTAL'!O15 -> 0 | I12: ='RESUMEN TOTAL'!P15 -> 0 | J12: ='RESUMEN TOTAL'!Q15 -> 0 | K12: ='RESUMEN TOTAL'!R15 -> 0 | L12: ='RESUMEN TOTAL'!S15 -> 0 | M12: ='RESUMEN TOTAL'!T15 -> 0 | ... AG12: ='RESUMEN TOTAL'!AN15 -> 0
A13: ='RESUMEN TOTAL'!A16 -> ALTAMIRA | B13: ='RESUMEN TOTAL'!B16 -> ALT 09 | C13: ='RESUMEN TOTAL'!D16 -> NECOCHEA Y CURUPAITY | D13: ='RESUMEN TOTAL'!E16 -> DOMO | E13: ='RESUMEN TOTAL'!F16 -> Fibra Optica | F13: ='RESUMEN TOTAL'!M16 -> 0 | G13: ='RESUMEN TOTAL'!N16 -> 0 | H13: ='RESUMEN TOTAL'!O16 -> 0 | I13: ='RESUMEN TOTAL'!P16 -> 0 | J13: ='RESUMEN TOTAL'!Q16 -> 0 | K13: ='RESUMEN TOTAL'!R16 -> 0 | L13: ='RESUMEN TOTAL'!S16 -> 0 | M13: ='RESUMEN TOTAL'!T16 -> 0 | ... AG13: ='RESUMEN TOTAL'!AN16 -> 0
A14: ='RESUMEN TOTAL'!A17 -> ALTAMIRA | B14: ='RESUMEN TOTAL'!B17 -> ALT 10 | C14: ='RESUMEN TOTAL'!D17 -> Calchaqui y Francia | D14: ='RESUMEN TOTAL'!E17 -> Domo | E14: ='RESUMEN TOTAL'!F17 -> GPON | F14: ='RESUMEN TOTAL'!M17 -> 0 | G14: ='RESUMEN TOTAL'!N17 -> 0 | H14: ='RESUMEN TOTAL'!O17 -> 0 | I14: ='RESUMEN TOTAL'!P17 -> 0 | J14: ='RESUMEN TOTAL'!Q17 -> 0 | K14: ='RESUMEN TOTAL'!R17 -> 0 | L14: ='RESUMEN TOTAL'!S17 -> 0 | M14: ='RESUMEN TOTAL'!T17 -> 0 | ... AG14: ='RESUMEN TOTAL'!AN17 -> 0
A15: ='RESUMEN TOTAL'!A18 -> ALTAMIRA | B15: ='RESUMEN TOTAL'!B18 -> ALT 11 | C15: CALCHAQUÍ Y GALARZA FIJA | D15: ='RESUMEN TOTAL'!E18 -> Fija | F15: ='RESUMEN TOTAL'!M18 -> 0 | G15: ='RESUMEN TOTAL'!N18 -> 0 | H15: ='RESUMEN TOTAL'!O18 -> 0 | I15: ='RESUMEN TOTAL'!P18 -> 0 | J15: ='RESUMEN TOTAL'!Q18 -> 0 | K15: ='RESUMEN TOTAL'!R18 -> 0 | L15: ='RESUMEN TOTAL'!S18 -> 0 | M15: ='RESUMEN TOTAL'!T18 -> 0 | ... AG15: ='RESUMEN TOTAL'!AN18 -> 0
A16: ='RESUMEN TOTAL'!A19 -> AGUSTIN RAMIREZ | B16: ='RESUMEN TOTAL'!B19 -> ARA 01 | C16: ='RESUMEN TOTAL'!D19 -> Malambo y Tranquera | D16: ='RESUMEN TOTAL'!E19 -> Domo | E16: ='RESUMEN TOTAL'!F19 -> Fibra Optica | F16: ='RESUMEN TOTAL'!M19 -> APAGADO | G16: ='RESUMEN TOTAL'!N19 -> APAGADO | H16: ='RESUMEN TOTAL'!O19 -> APAGADO | I16: ='RESUMEN TOTAL'!P19 -> APAGADO | J16: ='RESUMEN TOTAL'!Q19 -> APAGADO | K16: ='RESUMEN TOTAL'!R19 -> APAGADO | L16: ='RESUMEN TOTAL'!S19 -> 0 | M16: ='RESUMEN TOTAL'!T19 -> 0 | ... AG16: ='RESUMEN TOTAL'!AN19 -> 0
A17: ='RESUMEN TOTAL'!A22 -> BELGRANO | B17: ='RESUMEN TOTAL'!B22 -> BEL 01 | C17: ='RESUMEN TOTAL'!D22 -> San Martin y Dardo Rocha | D17: ='RESUMEN TOTAL'!E22 -> DOMO | E17: ='RESUMEN TOTAL'!F22 -> Fibra Optica | F17: ='RESUMEN TOTAL'!M22 -> 0 | G17: ='RESUMEN TOTAL'!N22 -> 0 | H17: ='RESUMEN TOTAL'!O22 -> 0 | I17: ='RESUMEN TOTAL'!P22 -> 0 | J17: ='RESUMEN TOTAL'!Q22 -> 0 | K17: ='RESUMEN TOTAL'!R22 -> 0 | L17: ='RESUMEN TOTAL'!S22 -> 0 | M17: ='RESUMEN TOTAL'!T22 -> 0 | ... AG17: ='RESUMEN TOTAL'!AN22 -> 0
A18: ='RESUMEN TOTAL'!A23 -> BELGRANO | B18: ='RESUMEN TOTAL'!B23 -> BEL 02 | C18: ='RESUMEN TOTAL'!D23 -> Guardia vieja y Fronteriz | D18: ='RESUMEN TOTAL'!E23 -> DOMO | E18: ='RESUMEN TOTAL'!F23 -> Fibra Optica | F18: ='RESUMEN TOTAL'!M23 -> 0 | G18: ='RESUMEN TOTAL'!N23 -> 0 | H18: ='RESUMEN TOTAL'!O23 -> 0 | I18: ='RESUMEN TOTAL'!P23 -> 0 | J18: ='RESUMEN TOTAL'!Q23 -> 0 | K18: ='RESUMEN TOTAL'!R23 -> 0 | L18: ='RESUMEN TOTAL'!S23 -> 0 | M18: ='RESUMEN TOTAL'!T23 -> 0 | ... AG18: ='RESUMEN TOTAL'!AN23 -> 0
A19: ='RESUMEN TOTAL'!A24 -> BOSQUES CENTRO | B19: ='RESUMEN TOTAL'!B24 -> BOSQC 01 | C19: ='RESUMEN TOTAL'!D24 -> LUIS AGOTE E/DANUNCIO Y CAMPOAMOR | D19: ='RESUMEN TOTAL'!E24 -> Fija | E19: ='RESUMEN TOTAL'!F24 -> PTO A FO | F19: ='RESUMEN TOTAL'!M24 -> 0 | G19: ='RESUMEN TOTAL'!N24 -> 0 | H19: ='RESUMEN TOTAL'!O24 -> 0 | I19: ='RESUMEN TOTAL'!P24 -> 0 | J19: ='RESUMEN TOTAL'!Q24 -> APAGADO | K19: ='RESUMEN TOTAL'!R24 -> APAGADO | L19: ='RESUMEN TOTAL'!S24 -> 0 | M19: ='RESUMEN TOTAL'!T24 -> 0 | ... AG19: ='RESUMEN TOTAL'!AN24 -> 0
A20: ='RESUMEN TOTAL'!A25 -> BOSQUES CENTRO | B20: ='RESUMEN TOTAL'!B25 -> BOSQC 02 | C20: ='RESUMEN TOTAL'!D25 -> LUIS AGOTE E/DANUNCIO Y CAMPOAMOR | D20: ='RESUMEN TOTAL'!E25 -> Fija | E20: ='RESUMEN TOTAL'!F25 -> PTO A FO | F20: ='RESUMEN TOTAL'!M25 -> 0 | G20: ='RESUMEN TOTAL'!N25 -> 0 | H20: ='RESUMEN TOTAL'!O25 -> 0 | I20: ='RESUMEN TOTAL'!P25 -> 0 | J20: ='RESUMEN TOTAL'!Q25 -> APAGADO | K20: ='RESUMEN TOTAL'!R25 -> APAGADO | L20: ='RESUMEN TOTAL'!S25 -> 0 | M20: ='RESUMEN TOTAL'!T25 -> 0 | ... AG20: ='RESUMEN TOTAL'!AN25 -> 0
A21: ='RESUMEN TOTAL'!A26 -> BOSQUES CENTRO | B21: ='RESUMEN TOTAL'!B26 -> BOSQC 03 | C21: ='RESUMEN TOTAL'!D26 -> BENAVENTE Y LUIS AGOTE | D21: ='RESUMEN TOTAL'!E26 -> Fija | E21: ='RESUMEN TOTAL'!F26 -> PTO A FO | F21: ='RESUMEN TOTAL'!M26 -> 0 | G21: ='RESUMEN TOTAL'!N26 -> 0 | H21: ='RESUMEN TOTAL'!O26 -> 0 | I21: ='RESUMEN TOTAL'!P26 -> 0 | J21: ='RESUMEN TOTAL'!Q26 -> APAGADO | K21: ='RESUMEN TOTAL'!R26 -> APAGADO | L21: ='RESUMEN TOTAL'!S26 -> 0 | M21: ='RESUMEN TOTAL'!T26 -> 0 | ... AG21: ='RESUMEN TOTAL'!AN26 -> 0
A22: ='RESUMEN TOTAL'!A27 -> BOSQUES CENTRO | B22: ='RESUMEN TOTAL'!B27 -> BOSQC 04 | C22: ='RESUMEN TOTAL'!D27 -> BENAVENTE Y LUIS AGOTE | D22: ='RESUMEN TOTAL'!E27 -> Fija | E22: ='RESUMEN TOTAL'!F27 -> PTO A FO | F22: ='RESUMEN TOTAL'!M27 -> 0 | G22: ='RESUMEN TOTAL'!N27 -> 0 | H22: ='RESUMEN TOTAL'!O27 -> 0 | I22: ='RESUMEN TOTAL'!P27 -> 0 | J22: ='RESUMEN TOTAL'!Q27 -> APAGADO | K22: ='RESUMEN TOTAL'!R27 -> APAGADO | L22: ='RESUMEN TOTAL'!S27 -> 0 | M22: ='RESUMEN TOTAL'!T27 -> 0 | ... AG22: ='RESUMEN TOTAL'!AN27 -> 0
A23: ='RESUMEN TOTAL'!A28 -> BOSQUES CENTRO | B23: ='RESUMEN TOTAL'!B28 -> BOSQC 05 | C23: ='RESUMEN TOTAL'!D28 -> LUIS AGOTE Y RUTA 36 | D23: ='RESUMEN TOTAL'!E28 -> Fija | E23: ='RESUMEN TOTAL'!F28 -> PTO A FO | F23: ='RESUMEN TOTAL'!M28 -> 0 | G23: ='RESUMEN TOTAL'!N28 -> 0 | H23: ='RESUMEN TOTAL'!O28 -> 0 | I23: ='RESUMEN TOTAL'!P28 -> 0 | J23: ='RESUMEN TOTAL'!Q28 -> 0 | K23: ='RESUMEN TOTAL'!R28 -> 0 | L23: ='RESUMEN TOTAL'!S28 -> 0 | M23: ='RESUMEN TOTAL'!T28 -> 0 | ... AG23: ='RESUMEN TOTAL'!AN28 -> 0
A24: ='RESUMEN TOTAL'!A29 -> BOSQUES CENTRO | B24: ='RESUMEN TOTAL'!B29 -> BOSQC 06 | C24: ='RESUMEN TOTAL'!D29 -> LUIS AGOTE Y RUTA 36 | D24: ='RESUMEN TOTAL'!E29 -> Fija | E24: ='RESUMEN TOTAL'!F29 -> PTO A FO | F24: ='RESUMEN TOTAL'!M29 -> 0 | G24: ='RESUMEN TOTAL'!N29 -> 0 | H24: ='RESUMEN TOTAL'!O29 -> 0 | I24: ='RESUMEN TOTAL'!P29 -> 0 | J24: ='RESUMEN TOTAL'!Q29 -> 0 | K24: ='RESUMEN TOTAL'!R29 -> 0 | L24: ='RESUMEN TOTAL'!S29 -> 0 | M24: ='RESUMEN TOTAL'!T29 -> 0 | ... AG24: ='RESUMEN TOTAL'!AN29 -> 0
A25: ='RESUMEN TOTAL'!A47 -> CENTRO | B25: ='RESUMEN TOTAL'!B47 -> CEN01 | C25: ='RESUMEN TOTAL'!D47 -> San Martin y 9 de Julio | D25: ='RESUMEN TOTAL'!E47 -> Fija | E25: ='RESUMEN TOTAL'!F47 -> Fibra Optica | F25: ='RESUMEN TOTAL'!M47 -> 0 | G25: ='RESUMEN TOTAL'!N47 -> 0 | H25: ='RESUMEN TOTAL'!O47 -> 0 | I25: ='RESUMEN TOTAL'!P47 -> 0 | J25: ='RESUMEN TOTAL'!Q47 -> 0 | K25: ='RESUMEN TOTAL'!R47 -> 0 | L25: ='RESUMEN TOTAL'!S47 -> 0 | M25: ='RESUMEN TOTAL'!T47 -> 0 | ... AG25: ='RESUMEN TOTAL'!AN47 -> 0
A26: ='RESUMEN TOTAL'!A48 -> CENTRO | B26: ='RESUMEN TOTAL'!B48 -> CEN02 | C26: ='RESUMEN TOTAL'!D48 -> San Martin y Almafuerte | D26: ='RESUMEN TOTAL'!E48 -> Fija | E26: ='RESUMEN TOTAL'!F48 -> Fibra Optica | F26: ='RESUMEN TOTAL'!M48 -> 0 | G26: ='RESUMEN TOTAL'!N48 -> 0 | H26: ='RESUMEN TOTAL'!O48 -> 0 | I26: ='RESUMEN TOTAL'!P48 -> 0 | J26: ='RESUMEN TOTAL'!Q48 -> 0 | K26: ='RESUMEN TOTAL'!R48 -> 0 | L26: ='RESUMEN TOTAL'!S48 -> 0 | M26: ='RESUMEN TOTAL'!T48 -> 0 | ... AG26: ='RESUMEN TOTAL'!AN48 -> 0
A27: ='RESUMEN TOTAL'!A49 -> CENTRO | B27: ='RESUMEN TOTAL'!B49 -> CEN03 | C27: ='RESUMEN TOTAL'!D49 -> San Martin y Sallares | D27: ='RESUMEN TOTAL'!E49 -> Domo | E27: ='RESUMEN TOTAL'!F49 -> Fibra Optica | F27: ='RESUMEN TOTAL'!M49 -> 0 | G27: ='RESUMEN TOTAL'!N49 -> 0 | H27: ='RESUMEN TOTAL'!O49 -> 0 | I27: ='RESUMEN TOTAL'!P49 -> 0 | J27: ='RESUMEN TOTAL'!Q49 -> 0 | K27: ='RESUMEN TOTAL'!R49 -> 0 | L27: ='RESUMEN TOTAL'!S49 -> 0 | M27: ='RESUMEN TOTAL'!T49 -> 0 | ... AG27: ='RESUMEN TOTAL'!AN49 -> 0
A28: ='RESUMEN TOTAL'!A50 -> CENTRO | B28: ='RESUMEN TOTAL'!B50 -> CEN04 | C28: ='RESUMEN TOTAL'!D50 -> San Martin y Contreras | D28: ='RESUMEN TOTAL'!E50 -> Domo | E28: ='RESUMEN TOTAL'!F50 -> Fibra Optica | F28: ='RESUMEN TOTAL'!M50 -> 0 | G28: ='RESUMEN TOTAL'!N50 -> 0 | H28: ='RESUMEN TOTAL'!O50 -> 0 | I28: ='RESUMEN TOTAL'!P50 -> 0 | J28: ='RESUMEN TOTAL'!Q50 -> 0 | K28: ='RESUMEN TOTAL'!R50 -> 0 | L28: ='RESUMEN TOTAL'!S50 -> 0 | M28: ='RESUMEN TOTAL'!T50 -> 0 | ... AG28: ='RESUMEN TOTAL'!AN50 -> 0
A29: ='RESUMEN TOTAL'!A51 -> CENTRO | B29: ='RESUMEN TOTAL'!B51 -> CEN 05 | C29: ='RESUMEN TOTAL'!D51 -> Bocuzzi e/España y San Martin | D29: ='RESUMEN TOTAL'!E51 -> DOMO | E29: ='RESUMEN TOTAL'!F51 -> Fibra Optica | F29: ='RESUMEN TOTAL'!M51 -> 0 | G29: ='RESUMEN TOTAL'!N51 -> 0 | H29: ='RESUMEN TOTAL'!O51 -> 0 | I29: ='RESUMEN TOTAL'!P51 -> 0 | J29: ='RESUMEN TOTAL'!Q51 -> 0 | K29: ='RESUMEN TOTAL'!R51 -> 0 | L29: ='RESUMEN TOTAL'!S51 -> 0 | M29: ='RESUMEN TOTAL'!T51 -> 0 | ... AG29: ='RESUMEN TOTAL'!AN51 -> 0
A30: ='RESUMEN TOTAL'!A52 -> CENTRO | B30: ='RESUMEN TOTAL'!B52 -> CEN06 | C30: ='RESUMEN TOTAL'!D52 -> Monteagudo y A.del Valle | D30: ='RESUMEN TOTAL'!E52 -> Fija | E30: ='RESUMEN TOTAL'!F52 -> Fibra Optica | F30: ='RESUMEN TOTAL'!M52 -> 0 | G30: ='RESUMEN TOTAL'!N52 -> 0 | H30: ='RESUMEN TOTAL'!O52 -> 0 | I30: ='RESUMEN TOTAL'!P52 -> APAGADO | J30: ='RESUMEN TOTAL'!Q52 -> 0 | K30: ='RESUMEN TOTAL'!R52 -> 0 | L30: ='RESUMEN TOTAL'!S52 -> 0 | M30: ='RESUMEN TOTAL'!T52 -> 0 | ... AG30: ='RESUMEN TOTAL'!AN52 -> 0
A31: ='RESUMEN TOTAL'!A53 -> CENTRO | B31: ='RESUMEN TOTAL'!B53 -> CEN07 | C31: ='RESUMEN TOTAL'!D53 -> San Martin y Guemes | D31: ='RESUMEN TOTAL'!E53 -> DOMO | E31: ='RESUMEN TOTAL'!F53 -> Fibra Optica | F31: ='RESUMEN TOTAL'!M53 -> 0 | G31: ='RESUMEN TOTAL'!N53 -> 0 | H31: ='RESUMEN TOTAL'!O53 -> 0 | I31: ='RESUMEN TOTAL'!P53 -> 0 | J31: ='RESUMEN TOTAL'!Q53 -> 0 | K31: ='RESUMEN TOTAL'!R53 -> 0 | L31: ='RESUMEN TOTAL'!S53 -> 0 | M31: ='RESUMEN TOTAL'!T53 -> 0 | ... AG31: ='RESUMEN TOTAL'!AN53 -> 0
A32: ='RESUMEN TOTAL'!A54 -> CENTRO | B32: ='RESUMEN TOTAL'!B54 -> CEN08 | C32: ='RESUMEN TOTAL'!D54 -> San Martin y Pte.Peron | D32: ='RESUMEN TOTAL'!E54 -> Domo | E32: ='RESUMEN TOTAL'!F54 -> Fibra Optica | F32: ='RESUMEN TOTAL'!M54 -> 0 | G32: ='RESUMEN TOTAL'!N54 -> 0 | H32: ='RESUMEN TOTAL'!O54 -> 0 | I32: ='RESUMEN TOTAL'!P54 -> 0 | J32: ='RESUMEN TOTAL'!Q54 -> 0 | K32: ='RESUMEN TOTAL'!R54 -> 0 | L32: ='RESUMEN TOTAL'!S54 -> 0 | M32: ='RESUMEN TOTAL'!T54 -> 0 | ... AG32: ='RESUMEN TOTAL'!AN54 -> 0
A33: ='RESUMEN TOTAL'!A55 -> CENTRO | B33: ='RESUMEN TOTAL'!B55 -> CEN09 | C33: ='RESUMEN TOTAL'!D55 -> Chacabuco y 25 de Mayo | D33: ='RESUMEN TOTAL'!E55 -> Domo | E33: ='RESUMEN TOTAL'!F55 -> Fibra Optica | F33: ='RESUMEN TOTAL'!M55 -> 0 | G33: ='RESUMEN TOTAL'!N55 -> 0 | H33: ='RESUMEN TOTAL'!O55 -> 0 | I33: ='RESUMEN TOTAL'!P55 -> 0 | J33: ='RESUMEN TOTAL'!Q55 -> 0 | K33: ='RESUMEN TOTAL'!R55 -> 0 | L33: ='RESUMEN TOTAL'!S55 -> 0 | M33: ='RESUMEN TOTAL'!T55 -> 0 | ... AG33: ='RESUMEN TOTAL'!AN55 -> 0
A34: ='RESUMEN TOTAL'!A56 -> CENTRO | B34: ='RESUMEN TOTAL'!B56 -> CEN10 | C34: ='RESUMEN TOTAL'!D56 -> Monteagudo y Pte. Peron | D34: ='RESUMEN TOTAL'!E56 -> Domo | E34: ='RESUMEN TOTAL'!F56 -> Fibra Optica | F34: ='RESUMEN TOTAL'!M56 -> 0 | G34: ='RESUMEN TOTAL'!N56 -> 0 | H34: ='RESUMEN TOTAL'!O56 -> 0 | I34: ='RESUMEN TOTAL'!P56 -> 0 | J34: ='RESUMEN TOTAL'!Q56 -> 0 | K34: ='RESUMEN TOTAL'!R56 -> 0 | L34: ='RESUMEN TOTAL'!S56 -> 0 | M34: ='RESUMEN TOTAL'!T56 -> 0 | ... AG34: ='RESUMEN TOTAL'!AN56 -> 0
A35: ='RESUMEN TOTAL'!A57 -> CENTRO | B35: ='RESUMEN TOTAL'!B57 -> CEN11 | C35: ='RESUMEN TOTAL'!D57 -> Monteagudo y Bocuzzi | D35: ='RESUMEN TOTAL'!E57 -> Domo | E35: ='RESUMEN TOTAL'!F57 -> Fibra Optica | F35: ='RESUMEN TOTAL'!M57 -> 0 | G35: ='RESUMEN TOTAL'!N57 -> 0 | H35: ='RESUMEN TOTAL'!O57 -> 0 | I35: ='RESUMEN TOTAL'!P57 -> 0 | J35: ='RESUMEN TOTAL'!Q57 -> 0 | K35: ='RESUMEN TOTAL'!R57 -> 0 | L35: ='RESUMEN TOTAL'!S57 -> 0 | M35: ='RESUMEN TOTAL'!T57 -> 0 | ... AG35: ='RESUMEN TOTAL'!AN57 -> 0
A36: ='RESUMEN TOTAL'!A58 -> CENTRO | B36: ='RESUMEN TOTAL'!B58 -> CEN 12 | C36: ='RESUMEN TOTAL'!D58 -> Monteagudo y Mitre | D36: ='RESUMEN TOTAL'!E58 -> Domo | E36: ='RESUMEN TOTAL'!F58 -> Fibra Optica | F36: ='RESUMEN TOTAL'!M58 -> 0 | G36: ='RESUMEN TOTAL'!N58 -> 0 | H36: ='RESUMEN TOTAL'!O58 -> 0 | I36: ='RESUMEN TOTAL'!P58 -> 0 | J36: ='RESUMEN TOTAL'!Q58 -> 0 | K36: ='RESUMEN TOTAL'!R58 -> 0 | L36: ='RESUMEN TOTAL'!S58 -> 0 | M36: ='RESUMEN TOTAL'!T58 -> 0 | ... AG36: ='RESUMEN TOTAL'!AN58 -> 0
... A71: ='RESUMEN TOTAL'!A93 -> CENTRO | B71: ='RESUMEN TOTAL'!B93 -> CEN47 | C71: ='RESUMEN TOTAL'!D93 -> Sallares y Brown | D71: ='RESUMEN TOTAL'!E93 -> Domo | E71: ='RESUMEN TOTAL'!F93 -> Fibra Optica | F71: ='RESUMEN TOTAL'!M93 -> 0 | G71: ='RESUMEN TOTAL'!N93 -> 0 | H71: ='RESUMEN TOTAL'!O93 -> 0 | I71: ='RESUMEN TOTAL'!P93 -> 0 | J71: ='RESUMEN TOTAL'!Q93 -> 0 | K71: ='RESUMEN TOTAL'!R93 -> 0 | L71: ='RESUMEN TOTAL'!S93 -> 0 | M71: ='RESUMEN TOTAL'!T93 -> 0 | ... AG71: ='RESUMEN TOTAL'!AN93 -> 0
A72: ='RESUMEN TOTAL'!A94 -> CENTRO | B72: ='RESUMEN TOTAL'!B94 -> CEN48 | C72: ='RESUMEN TOTAL'!D94 -> Velez Sarsfield y Las Heras | D72: ='RESUMEN TOTAL'!E94 -> Domo | E72: ='RESUMEN TOTAL'!F94 -> GPON | F72: ='RESUMEN TOTAL'!M94 -> 0 | G72: ='RESUMEN TOTAL'!N94 -> 0 | H72: ='RESUMEN TOTAL'!O94 -> 0 | I72: ='RESUMEN TOTAL'!P94 -> 0 | J72: ='RESUMEN TOTAL'!Q94 -> 0 | K72: ='RESUMEN TOTAL'!R94 -> 0 | L72: ='RESUMEN TOTAL'!S94 -> 0 | M72: ='RESUMEN TOTAL'!T94 -> 0 | ... Z72: ='RESUMEN TOTAL'!AG94 -> 0 | AA72: ='RESUMEN TOTAL'!#REF! -> #REF! | AB72: ='RESUMEN TOTAL'!AI94 -> 0 | AC72: ='RESUMEN TOTAL'!AJ94 -> 0 | AD72: ='RESUMEN TOTAL'!AK94 -> 0 | AE72: ='RESUMEN TOTAL'!AL94 -> 0 | AF72: ='RESUMEN TOTAL'!AM94 -> 0 | AG72: ='RESUMEN TOTAL'!AN94 -> 0
A73: ='RESUMEN TOTAL'!A95 -> CENTRO | B73: ='RESUMEN TOTAL'!B95 -> CEN49 | C73: ='RESUMEN TOTAL'!D95 -> Av. San Martin y Florencio Sanchez | D73: ='RESUMEN TOTAL'!E95 -> Domo | E73: ='RESUMEN TOTAL'!F95 -> Fibra Optica | F73: ='RESUMEN TOTAL'!M95 -> 0 | G73: ='RESUMEN TOTAL'!N95 -> 0 | H73: ='RESUMEN TOTAL'!O95 -> 0 | I73: ='RESUMEN TOTAL'!P95 -> 0 | J73: ='RESUMEN TOTAL'!Q95 -> 0 | K73: ='RESUMEN TOTAL'!R95 -> 0 | L73: ='RESUMEN TOTAL'!S95 -> 0 | M73: ='RESUMEN TOTAL'!T95 -> 0 | ... AG73: ='RESUMEN TOTAL'!AN95 -> 0
A74: ='RESUMEN TOTAL'!A96 -> CENTRO | B74: ='RESUMEN TOTAL'!B96 -> CEN 50 | C74: ='RESUMEN TOTAL'!D96 -> Av. San Martin y Newbery | D74: ='RESUMEN TOTAL'!E96 -> Domo | E74: ='RESUMEN TOTAL'!F96 -> GPON | F74: ='RESUMEN TOTAL'!M96 -> APAGADO | G74: ='RESUMEN TOTAL'!N96 -> 0 | H74: ='RESUMEN TOTAL'!O96 -> 0 | I74: ='RESUMEN TOTAL'!P96 -> 0 | J74: ='RESUMEN TOTAL'!Q96 -> 0 | K74: ='RESUMEN TOTAL'!R96 -> 0 | L74: ='RESUMEN TOTAL'!S96 -> 0 | M74: ='RESUMEN TOTAL'!T96 -> 0 | ... AG74: ='RESUMEN TOTAL'!AN96 -> 0
...

Sheet Hoja1
B1: CAMARAS | C1: 45992
A2: BONOMO | B2: =COUNTIFS('RESUMEN TOTAL'!C8:C621,"=BONOMO") -> 308 | C2: 0 | F2: 46054 | G2: 46055 | H2: 46056 | I2: 46057 | J2: 46058 | K2: 46059 | L2: 46060 | M2: 46061 | N2: 46062 | O2: 46063 | P2: 46064 | Q2: 46065 | R2: 46066 | S2: 46067 | T2: 46068 | U2: 46069 | V2: 46070 | W2: 46071 | X2: 46072 | Y2: 46073 | Z2: 46074 | AA2: 46075 | AB2: 46076 | AC2: 46077 | AD2: 46078 | AE2: 46079 | AF2: 46080 | AG2: 46081
C3: 0 | D3: BONOMO | E3: APAGADAS BONOMO | F3: 0 | G3: 27 | H3: 0 | I3: 0 | J3: 29 | K3: =COUNTIFS('RESUMEN TOTAL'!R8:R698,"=APAGADO",'RESUMEN TOTAL'!C8:C698,"=BONOMO") -> 29 | L3: 0 | M3: 0 | N3: =COUNTIFS('RESUMEN TOTAL'!U8:U698,"=APAGADO",'RESUMEN TOTAL'!C8:C698,"=BONOMO") -> 26 | O3: =COUNTIFS('RESUMEN TOTAL'!V8:V698,"=APAGADO",'RESUMEN TOTAL'!C8:C698,"=BONOMO") -> 27 | P3: =COUNTIFS('RESUMEN TOTAL'!W8:W698,"=APAGADO",'RESUMEN TOTAL'!C8:C698,"=BONOMO") -> 25 | Q3: =COUNTIFS('RESUMEN TOTAL'!X8:X698,"=APAGADO",'RESUMEN TOTAL'!C8:C698,"=BONOMO") -> 38 | R3: =COUNTIFS('RESUMEN TOTAL'!Y8:Y698,"=APAGADO",'RESUMEN TOTAL'!C8:C698,"=BONOMO") -> 0 | S3: =COUNTIFS('RESUMEN TOTAL'!Z8:Z698,"=APAGADO",'RESUMEN TOTAL'!C8:C698,"=BONOMO") -> 0 | T3: =COUNTIFS('RESUMEN TOTAL'!AA8:AA698,"=APAGADO",'RESUMEN TOTAL'!C8:C698,"=BONOMO") -> 0 | U3: =COUNTIFS('RESUMEN TOTAL'!AB8:AB698,"=APAGADO",'RESUMEN TOTAL'!C8:C698,"=BONOMO") -> 0 | V3: =COUNTIFS('RESUMEN TOTAL'!AC8:AC698,"=APAGADO",'RESUMEN TOTAL'!C8:C698,"=BONOMO") -> 0 | W3: 0 | X3: =COUNTIFS('RESUMEN TOTAL'!AE8:AE698,"=APAGADO",'RESUMEN TOTAL'!C8:C698,"=BONOMO") -> 0 | Y3: =COUNTIFS('RESUMEN TOTAL'!AF8:AF698,"=APAGADO",'RESUMEN TOTAL'!C8:C698,"=BONOMO") -> 0 | Z3: =COUNTIFS('RESUMEN TOTAL'!AG8:AG698,"=APAGADO",'RESUMEN TOTAL'!C8:C698,"=BONOMO") -> 0 | AA3: =COUNTIFS('RESUMEN TOTAL'!AH8:AH698,"=APAGADO",'RESUMEN TOTAL'!C8:C698,"=BONOMO") -> 0 | AB3: =COUNTIFS('RESUMEN TOTAL'!AI8:AI698,"=APAGADO",'RESUMEN TOTAL'!C8:C698,"=BONOMO") -> 0 | AC3: =COUNTIFS('RESUMEN TOTAL'!AJ8:AJ698,"=APAGADO",'RESUMEN TOTAL'!C8:C698,"=BONOMO") -> 0 | AD3: =COUNTIFS('RESUMEN TOTAL'!AK8:AK698,"=APAGADO",'RESUMEN TOTAL'!C8:C698,"=BONOMO") -> 0 | AE3: 29 | AF3: =COUNTIFS('RESUMEN TOTAL'!AM8:AM698,"=APAGADO",'RESUMEN TOTAL'!C8:C698,"=BONOMO") -> 0 | AG3: =COUNTIFS('RESUMEN TOTAL'!AN8:AN698,"=APAGADO",'RESUMEN TOTAL'!C8:C698,"=BONOMO") -> 0
A4: COSEIDI | B4: =COUNTIFS('RESUMEN TOTAL'!C8:C621,"=COSEIDI") -> 276 | C4: 0 | E4: % BONOMO | F4: 0 | G4: =G3/BONOMOcam -> 0.087662338 | H4: =H3/BONOMOcam -> 0 | I4: 0 | J4: 0.09 | K4: =K3/BONOMOcam -> 0.094155844 | L4: =L3/BONOMOcam -> 0 | M4: 0 | N4: =N3/BONOMOcam -> 0.084415584 | O4: =O3/BONOMOcam -> 0.087662338 | P4: =P3/BONOMOcam -> 0.081168831 | Q4: =Q3/BONOMOcam -> 0.12337662 | R4: =R3/BONOMOcam -> 0 | S4: =S3/BONOMOcam -> 0 | T4: =T3/BONOMOcam -> 0 | U4: =U3/BONOMOcam -> 0 | V4: =V3/BONOMOcam -> 0 | W4: 0 | X4: =X3/BONOMOcam -> 0 | Y4: =Y3/BONOMOcam -> 0 | Z4: =Z3/BONOMOcam -> 0 | AA4: =AA3/BONOMOcam -> 0 | AB4: =AB3/BONOMOcam -> 0 | AC4: 0 | AD4: =AD3/BONOMOcam -> 0 | AE4: =AE3/BONOMOcam -> 0.094155844 | AF4: =AF3/BONOMOcam -> 0 | AG4: =AG3/BONOMOcam -> 0
C5: 0 | D5: COSEIDI | E5: APAGADAS COSEIDI | F5: 0 | G5: 41 | H5: 0 | I5: 0 | J5: =COUNTIFS('RESUMEN TOTAL'!Q10:Q700,"=APAGADO",'RESUMEN TOTAL'!C10:C700,"=COSEIDI") -> 39 | K5: =COUNTIFS('RESUMEN TOTAL'!R10:R700,"=APAGADO",'RESUMEN TOTAL'!C10:C700,"=COSEIDI") -> 43 | L5: =COUNTIFS('RESUMEN TOTAL'!S10:S700,"=APAGADO",'RESUMEN TOTAL'!C10:C700,"=COSEIDI") -> 0 | M5: 0 | N5: =COUNTIFS('RESUMEN TOTAL'!U10:U700,"=APAGADO",'RESUMEN TOTAL'!C10:C700,"=COSEIDI") -> 54 | O5: =COUNTIFS('RESUMEN TOTAL'!V10:V700,"=APAGADO",'RESUMEN TOTAL'!C10:C700,"=COSEIDI") -> 76 | P5: =COUNTIFS('RESUMEN TOTAL'!W10:W700,"=APAGADO",'RESUMEN TOTAL'!C10:C700,"=COSEIDI") -> 59 | Q5: =COUNTIFS('RESUMEN TOTAL'!X10:X700,"=APAGADO",'RESUMEN TOTAL'!C10:C700,"=COSEIDI") -> 54 | R5: =COUNTIFS('RESUMEN TOTAL'!Y10:Y700,"=APAGADO",'RESUMEN TOTAL'!C10:C700,"=COSEIDI") -> 0 | S5: =COUNTIFS('RESUMEN TOTAL'!Z10:Z700,"=APAGADO",'RESUMEN TOTAL'!C10:C700,"=COSEIDI") -> 0 | T5: 0 | U5: 0 | V5: =COUNTIFS('RESUMEN TOTAL'!AC10:AC700,"=APAGADO",'RESUMEN TOTAL'!C10:C700,"=COSEIDI") -> 0 | W5: =COUNTIFS('RESUMEN TOTAL'!AD10:AD700,"=APAGADO",'RESUMEN TOTAL'!C10:C700,"=COSEIDI") -> 0 | X5: =COUNTIFS('RESUMEN TOTAL'!AE10:AE700,"=APAGADO",'RESUMEN TOTAL'!C10:C700,"=COSEIDI") -> 0 | Y5: =COUNTIFS('RESUMEN TOTAL'!AF10:AF700,"=APAGADO",'RESUMEN TOTAL'!C10:C700,"=COSEIDI") -> 0 | Z5: =COUNTIFS('RESUMEN TOTAL'!AG10:AG700,"=APAGADO",'RESUMEN TOTAL'!C10:C700,"=COSEIDI") -> 0 | AA5: =COUNTIFS('RESUMEN TOTAL'!AH10:AH700,"=APAGADO",'RESUMEN TOTAL'!C10:C700,"=COSEIDI") -> 0 | AB5: =COUNTIFS('RESUMEN TOTAL'!AI10:AI700,"=APAGADO",'RESUMEN TOTAL'!C10:C700,"=COSEIDI") -> 0 | AC5: =COUNTIFS('RESUMEN TOTAL'!AJ10:AJ700,"=APAGADO",'RESUMEN TOTAL'!C10:C700,"=COSEIDI") -> 0 | AD5: =COUNTIFS('RESUMEN TOTAL'!AK10:AK700,"=APAGADO",'RESUMEN TOTAL'!C10:C700,"=COSEIDI") -> 0 | AE5: =COUNTIFS('RESUMEN TOTAL'!AL10:AL700,"=APAGADO",'RESUMEN TOTAL'!C10:C700,"=COSEIDI") -> 0 | AF5: 0 | AG5: 0
E6: % COSEIDI | F6: 0 | G6: =G5/COSEIDIcam -> 0.14855072 | H6: 0 | I6: 0 | J6: 0.14 | K6: =K5/COSEIDIcam -> 0.1557971 | L6: =L5/COSEIDIcam -> 0 | M6: 0 | N6: =N5/COSEIDIcam -> 0.19565217 | O6: =O5/COSEIDIcam -> 0.27536232 | P6: 0 | Q6: =Q5/COSEIDIcam -> 0.19565217 | R6: =R5/COSEIDIcam -> 0 | S6: =S5/COSEIDIcam -> 0 | T6: 0 | U6: 0 | V6: 0 | W6: =W5/COSEIDIcam -> 0 | X6: =X5/COSEIDIcam -> 0 | Y6: =Y5/COSEIDIcam -> 0 | Z6: =Z5/COSEIDIcam -> 0 | AA6: =AA5/COSEIDIcam -> 0 | AB6: =AB5/COSEIDIcam -> 0 | AC6: 0 | AD6: =AD5/COSEIDIcam -> 0 | AE6: =AE5/COSEIDIcam -> 0 | AF6: =AF5/COSEIDIcam -> 0 | AG6: 0

Sheet informe
C1: CANTIDAD | D1: APAGADAS | E1: %
B2: TOTAL | C2: =CANTIDAD_DE_CAMARAS -> 584 | F2: 46054
A3: L | B3: CAIDAS | C3: ='RESUMEN TOTAL'!M3 -> 69 | E3: =C3/C2 -> 0.11815068
B4: LLEGAMOS NOSOTROS | C4: 0 | D4: 0 | E4: =D4/C2 -> 0
B5: NO ESTA LA CAMARA | C5: 0 | D5: 0 | E5: =D5/C2 -> 0
A6: L | B6: RADIO | C6: 0 | D6: 0 | E6: =D6/C2 -> 0
C7: 0 | D7: 0 | E7: =D7/C2 -> 0
C8: CANTIDAD | D8: APAGADAS | E8: %
A9: F | B9: BONOMO | C9: 307
A10: F | B10: COSEIDI | C10: =COSEIDIcam -> 276 | D10: =Hoja1!F5 -> 0
C12: CANTIDAD | D12: APAGADAS | E12: %
B13: TOTAL | C13: =CANTIDAD_DE_CAMARAS -> 584 | F13: 46055
A14: M | B14: CAIDAS | C14: 68 | E14: =C14/C13 -> 0.11643836
B15: LLEGAMOS NOSOTROS | C15: 2 | D15: 66 | E15: =D15/C13 -> 0.1130137
B16: NO ESTA LA CAMARA | C16: 6 | D16: 60 | E16: =D16/C13 -> 0.10273973
A17: M | B17: RADIO | C17: 3 | D17: =D16-C17 -> 57 | E17: =D17/C13 -> 0.09760274
D18: 0 | E18: =D18/C13 -> 0
C19: CANTIDAD | D19: APAGADAS | E19: %
A20: G | B20: BONOMO | C20: 307 | D20: 27 | E20: =D20/C20 -> 0.087947883
A21: G | B21: COSEIDI | C21: =COSEIDIcam -> 276 | D21: 41 | E21: =D21/C21 -> 0.14855072
C23: CANTIDAD | D23: APAGADAS | E23: %
B24: TOTAL | C24: =CANTIDAD_DE_CAMARAS -> 584 | F24: 46056
A25: N | B25: CAIDAS | C25: ='RESUMEN TOTAL'!O3 -> 66 | E25: =C25/C24 -> 0.1130137
B26: LLEGAMOS NOSOTROS | C26: 9 | D26: =C25-C26 -> 57 | E26: =D26/C24 -> 0.09760274
B27: NO ESTA LA CAMARA | C27: 8 | D27: =D26-C27 -> 49 | E27: =D27/C24 -> 0.08390411
A28: N | B28: RADIO | C28: ='RESUMEN TOTAL'!O5 -> 2 | D28: =D27-C28 -> 47 | E28: =D28/C24 -> 0.080479452
C29: 0 | D29: =D28-C29 -> 47 | E29: =D29/C24 -> 0.080479452
C30: CANTIDAD | D30: APAGADAS | E30: %
B31: BONOMO | C31: 307 | D31: 26 | E31: =D31/C31 -> 0.084690554
B32: COSEIDI | C32: =COSEIDIcam -> 276 | D32: 40 | E32: =D32/C32 -> 0.14492754
C34: CANTIDAD | D34: APAGADAS | E34: %
B35: TOTAL | C35: =CANTIDAD_DE_CAMARAS -> 584 | F35: 46057
A36: O | B36: CAIDAS | C36: ='RESUMEN TOTAL'!P3 -> 71 | E36: =C36/C35 -> 0.12157534
B37: LLEGAMOS NOSOTROS | C37: 0 | D37: 0 | E37: =D37/C35 -> 0
B38: NO ESTA LA CAMARA | C38: 0 | D38: 0 | E38: =D38/C35 -> 0
A39: O | B39: RADIO | C39: 0 | D39: =D38-C39 -> 0 | E39: =D39/C35 -> 0
C40: 0 | D40: 0 | E40: =D40/C35 -> 0
C41: CANTIDAD | D41: APAGADAS | E41: %
B42: BONOMO | C42: 307 | D42: 0 | E42: =D42/C42 -> 0
B43: COSEIDI | C43: =COSEIDIcam -> 276 | D43: =Hoja1!I5 -> 0 | E43: 0.24
...
